#VRML_SIM R2023b utf8

EXTERNPROTO "https://raw.githubusercontent.com/cyberbotics/webots/R2023b/projects/objects/backgrounds/protos/TexturedBackground.proto"
EXTERNPROTO "https://raw.githubusercontent.com/cyberbotics/webots/R2023b/projects/objects/backgrounds/protos/TexturedBackgroundLight.proto"
EXTERNPROTO "https://raw.githubusercontent.com/cyberbotics/webots/R2023b/projects/objects/floors/protos/RectangleArena.proto"

WorldInfo {
  contactProperties [
    ContactProperties {
      coulombFriction [
        0.8
      ]
      bounce 0.1
    }
  ]
}
Viewpoint {
  orientation -0.10302879694098728 -0.3170004009971241 0.9428127135166111 4.31289098620846
  position 0.24884420924765827 0.29091253393433125 0.37354806432577614
}
TexturedBackground {
}
TexturedBackgroundLight {
}
RectangleArena {
}
Robot {
  translation 0 0 0.21
  children [
    DEF central_body Solid {
      children [
        DEF central_body_shape Shape {
          appearance Appearance {
            material Material {
            }
          }
          geometry Mesh {
            url [
              "../openduck_in_solvespace/split_parts/part_1.obj"
            ]
          }
        }
        DEF first_motor_shape Shape {
          appearance Appearance {
            material Material {
            }
          }
          geometry Mesh {
            url [
              "../openduck_in_solvespace/split_parts/part_5.obj"
            ]
          }
        }
      ]
      name "central_body"
      boundingObject Group {
        children [
          Mesh {
            url [
              "../openduck_in_solvespace/split_parts/part_1.obj"
            ]
          }
          Mesh {
            url [
              "../openduck_in_solvespace/split_parts/part_5.obj"
            ]
          }
        ]
      }
    }
    HingeJoint {
      jointParameters HingeJointParameters {
        axis 0 0 1
        anchor 0.07 0 0.05222
      }
      device [
        RotationalMotor {
          name "t1"
        }
        PositionSensor {
          name "t1_sensor"
        }
      ]
      endPoint DEF second_motor Solid {
        children [
          Shape {
            appearance Appearance {
              material Material {
              }
            }
            geometry Mesh {
              url [
                "../openduck_in_solvespace/split_parts/part_2.obj"
              ]
            }
          }
          DEF left_shoulder HingeJoint {
            jointParameters HingeJointParameters {
              axis 0 1 0
              anchor 0.07 -0.0145 0.0175
            }
            device [
              RotationalMotor {
                name "t2"
              }
              PositionSensor {
                name "t2_sensor"
              }
            ]
            endPoint DEF left_shoulder Solid {
              rotation 0 1 0 0
              children [
                DEF left_shoulder_shape Shape {
                  appearance Appearance {
                    material Material {
                    }
                  }
                  geometry Mesh {
                    url [
                      "../openduck_in_solvespace/split_parts/part_6.obj"
                    ]
                  }
                }
              ]
              name "left_shoulder"
              boundingObject Mesh {
                url [
                  "../openduck_in_solvespace/split_parts/part_6.obj"
                ]
              }
              physics Physics {
              }
            }
          }
        ]
        name "second_motor"
        boundingObject Mesh {
          url [
            "../openduck_in_solvespace/split_parts/part_2.obj"
          ]
        }
        physics Physics {
        }
      }
    }
  ]
  boundingObject Group {
    children [
      DEF central_body Mesh {
        url [
          "../openduck_in_solvespace/split_parts/part_1.obj"
        ]
      }
      DEF first_motor Mesh {
        url [
          "../openduck_in_solvespace/split_parts/part_5.obj"
        ]
      }
    ]
  }
  controller "openduck_controller"
  selfCollision TRUE
}
