#VRML_SIM R2023b utf8

EXTERNPROTO "https://raw.githubusercontent.com/cyberbotics/webots/R2023b/projects/objects/backgrounds/protos/TexturedBackground.proto"
EXTERNPROTO "https://raw.githubusercontent.com/cyberbotics/webots/R2023b/projects/objects/backgrounds/protos/TexturedBackgroundLight.proto"
EXTERNPROTO "https://raw.githubusercontent.com/cyberbotics/webots/R2023b/projects/objects/floors/protos/RectangleArena.proto"

WorldInfo {
  basicTimeStep 16
  contactProperties [
    ContactProperties {
      coulombFriction [
        0.8
      ]
      bounce 0.1
    }
  ]
}
Viewpoint {
  orientation -0.13529582444924312 -0.035629881986568426 0.9901644062458632 3.891441569097635
  position 0.4069526312958618 0.32611132346833954 0.24339429482157832
}
TexturedBackground {
}
TexturedBackgroundLight {
}
RectangleArena {
}
Robot {
  translation 0 0 0.09
  rotation 0 0 1 4.692820414042842e-06
  children [
    DEF central_body Solid {
      children [
        DEF central_body_shape Shape {
          appearance Appearance {
            material Material {
            }
          }
          geometry Mesh {
            url [
              "../openduck_in_solvespace/checked_repaired_simplified/part_1_repaired_simplified.obj"
            ]
          }
        }
        DEF first_motor_shape Shape {
          appearance Appearance {
            material Material {
            }
          }
          geometry Mesh {
            url [
              "../openduck_in_solvespace/checked_repaired_simplified/part_5_repaired_simplified.obj"
            ]
          }
        }
      ]
      name "central_body"
      boundingObject Group {
        children [
          Mesh {
            url [
              "../openduck_in_solvespace/checked_repaired_simplified/part_1_repaired_simplified.obj"
            ]
          }
          Mesh {
            url [
              "../openduck_in_solvespace/checked_repaired_simplified/part_5_repaired_simplified.obj"
            ]
          }
        ]
      }
      physics Physics {
      }
    }
    HingeJoint {
      jointParameters HingeJointParameters {
        axis 0 0 1
        anchor 0.07 0 0.05222
      }
      device [
        RotationalMotor {
          name "t1"
        }
        PositionSensor {
          name "t1_sensor"
        }
      ]
      endPoint DEF second_motor Solid {
        translation -4.163336342344337e-17 3.469446951953614e-18 0
        children [
          DEF second_motor_shape Shape {
            appearance Appearance {
              material Material {
              }
            }
            geometry Mesh {
              url [
                "../openduck_in_solvespace/checked_repaired_simplified/part_2_repaired_simplified.obj"
              ]
            }
          }
          DEF left_shoulder HingeJoint {
            jointParameters HingeJointParameters {
              axis 0 1 0
              anchor 0.07 -0.0145 0.0175
            }
            device [
              RotationalMotor {
                name "t2"
              }
              PositionSensor {
                name "t2_sensor"
              }
            ]
            endPoint DEF left_shoulder Solid {
              translation 5.551115123125783e-17 -2.0816681711721685e-17 6.938893903907228e-18
              rotation 0 1 0 0
              children [
                DEF left_shoulder_shape Shape {
                  appearance Appearance {
                    material Material {
                    }
                  }
                  geometry Mesh {
                    url [
                      "../openduck_in_solvespace/checked_repaired_simplified/part_6_repaired_simplified.obj"
                    ]
                  }
                }
                DEF third_motor_shape Shape {
                  appearance Appearance {
                    material Material {
                    }
                  }
                  geometry Mesh {
                    url [
                      "../openduck_in_solvespace/split_parts/part_8.obj"
                    ]
                  }
                }
                HingeJoint {
                  jointParameters HingeJointParameters {
                    anchor 0.15313 0.01464 0.01652
                  }
                  device [
                    RotationalMotor {
                      name "t3"
                    }
                    PositionSensor {
                      name "t3_sensor"
                    }
                  ]
                  endPoint DEF third_motor Solid {
                    translation 1.1102230246251565e-16 5.204170427930421e-18 3.469446951953614e-18
                    rotation 1 0 0 0
                    children [
                      DEF left_leg_1_shape Shape {
                        appearance Appearance {
                          material Material {
                          }
                        }
                        geometry Mesh {
                          url [
                            "../openduck_in_solvespace/split_parts/part_10.obj"
                          ]
                        }
                      }
                      DEF left_leg_2_shape Shape {
                        appearance Appearance {
                          material Material {
                          }
                        }
                        geometry Mesh {
                          url [
                            "../openduck_in_solvespace/split_parts/part_11.obj"
                          ]
                        }
                      }
                    ]
                    boundingObject Group {
                      children [
                        Mesh {
                          url [
                            "../openduck_in_solvespace/split_parts/part_10.obj"
                          ]
                        }
                        Mesh {
                          url [
                            "../openduck_in_solvespace/split_parts/part_11.obj"
                          ]
                        }
                      ]
                    }
                    physics Physics {
                    }
                  }
                }
              ]
              name "left_shoulder"
              boundingObject Mesh {
                url [
                  "../openduck_in_solvespace/checked_repaired_simplified/part_6_repaired_simplified.obj"
                ]
              }
              physics Physics {
              }
            }
          }
        ]
        name "second_motor"
        boundingObject Mesh {
          url [
            "../openduck_in_solvespace/checked_repaired_simplified/part_2_repaired_simplified.obj"
          ]
        }
        physics Physics {
        }
      }
    }
  ]
  boundingObject Group {
    children [
      DEF central_body Mesh {
        url [
          "../openduck_in_solvespace/split_parts/part_1.obj"
        ]
      }
      DEF first_motor Mesh {
        url [
          "../openduck_in_solvespace/split_parts/part_5.obj"
        ]
      }
    ]
  }
  physics Physics {
  }
  controller "t1_t2_t3_sync"
  selfCollision TRUE
}
